Watching for file changes with StatReloader
D:\projects\kindbite\backend\apps\users\models.py changed, reloading.
Watching for file changes with StatReloader
Watching for file changes with StatReloader
"GET /api/v1/auth/status/ HTTP/1.1" 200 38
Internal Server Error: /api/v1/auth/register/
Traceback (most recent call last):
  File "D:\projects\kindbite\backend\venv\Lib\site-packages\django\db\backends\utils.py", line 89, in _execute
    return self.cursor.execute(sql, params)
           ~~~~~~~~~~~~~~~~~~~^^^^^^^^^^^^^
  File "D:\projects\kindbite\backend\venv\Lib\site-packages\django\db\backends\sqlite3\base.py", line 328, in execute
    return super().execute(query, params)
           ~~~~~~~~~~~~~~~^^^^^^^^^^^^^^^
sqlite3.OperationalError: no such table: users

The above exception was the direct cause of the following exception:

Traceback (most recent call last):
  File "D:\projects\kindbite\backend\venv\Lib\site-packages\django\core\handlers\exception.py", line 55, in inner
    response = get_response(request)
  File "D:\projects\kindbite\backend\venv\Lib\site-packages\django\core\handlers\base.py", line 197, in _get_response
    response = wrapped_callback(request, *callback_args, **callback_kwargs)
  File "D:\projects\kindbite\backend\venv\Lib\site-packages\django\views\decorators\csrf.py", line 56, in wrapper_view
    return view_func(*args, **kwargs)
  File "D:\projects\kindbite\backend\venv\Lib\site-packages\django\views\generic\base.py", line 104, in view
    return self.dispatch(request, *args, **kwargs)
           ~~~~~~~~~~~~~^^^^^^^^^^^^^^^^^^^^^^^^^^
  File "D:\projects\kindbite\backend\venv\Lib\site-packages\rest_framework\views.py", line 509, in dispatch
    response = self.handle_exception(exc)
  File "D:\projects\kindbite\backend\venv\Lib\site-packages\rest_framework\views.py", line 469, in handle_exception
    self.raise_uncaught_exception(exc)
    ~~~~~~~~~~~~~~~~~~~~~~~~~~~~~^^^^^
  File "D:\projects\kindbite\backend\venv\Lib\site-packages\rest_framework\views.py", line 480, in raise_uncaught_exception
    raise exc
  File "D:\projects\kindbite\backend\venv\Lib\site-packages\rest_framework\views.py", line 506, in dispatch
    response = handler(request, *args, **kwargs)
  File "D:\projects\kindbite\backend\venv\Lib\site-packages\rest_framework\decorators.py", line 50, in handler
    return func(*args, **kwargs)
  File "D:\projects\kindbite\backend\apps\authentication\views.py", line 56, in register
    if serializer.is_valid():
       ~~~~~~~~~~~~~~~~~~~^^
  File "D:\projects\kindbite\backend\venv\Lib\site-packages\rest_framework\serializers.py", line 227, in is_valid
    self._validated_data = self.run_validation(self.initial_data)
                           ~~~~~~~~~~~~~~~~~~~^^^^^^^^^^^^^^^^^^^
  File "D:\projects\kindbite\backend\venv\Lib\site-packages\rest_framework\serializers.py", line 426, in run_validation
    value = self.to_internal_value(data)
  File "D:\projects\kindbite\backend\venv\Lib\site-packages\rest_framework\serializers.py", line 483, in to_internal_value
    validated_value = field.run_validation(primitive_value)
  File "D:\projects\kindbite\backend\venv\Lib\site-packages\rest_framework\fields.py", line 751, in run_validation
    return super().run_validation(data)
           ~~~~~~~~~~~~~~~~~~~~~~^^^^^^
  File "D:\projects\kindbite\backend\venv\Lib\site-packages\rest_framework\fields.py", line 548, in run_validation
    self.run_validators(value)
    ~~~~~~~~~~~~~~~~~~~^^^^^^^
  File "D:\projects\kindbite\backend\venv\Lib\site-packages\rest_framework\fields.py", line 560, in run_validators
    validator(value, self)
    ~~~~~~~~~^^^^^^^^^^^^^
  File "D:\projects\kindbite\backend\venv\Lib\site-packages\rest_framework\validators.py", line 73, in __call__
    if qs_exists(queryset):
       ~~~~~~~~~^^^^^^^^^^
  File "D:\projects\kindbite\backend\venv\Lib\site-packages\rest_framework\validators.py", line 21, in qs_exists
    return queryset.exists()
           ~~~~~~~~~~~~~~~^^
  File "D:\projects\kindbite\backend\venv\Lib\site-packages\django\db\models\query.py", line 1241, in exists
    return self.query.has_results(using=self.db)
           ~~~~~~~~~~~~~~~~~~~~~~^^^^^^^^^^^^^^^
  File "D:\projects\kindbite\backend\venv\Lib\site-packages\django\db\models\sql\query.py", line 598, in has_results
    return compiler.has_results()
           ~~~~~~~~~~~~~~~~~~~~^^
  File "D:\projects\kindbite\backend\venv\Lib\site-packages\django\db\models\sql\compiler.py", line 1530, in has_results
    return bool(self.execute_sql(SINGLE))
                ~~~~~~~~~~~~~~~~^^^^^^^^
  File "D:\projects\kindbite\backend\venv\Lib\site-packages\django\db\models\sql\compiler.py", line 1562, in execute_sql
    cursor.execute(sql, params)
    ~~~~~~~~~~~~~~^^^^^^^^^^^^^
  File "D:\projects\kindbite\backend\venv\Lib\site-packages\django\db\backends\utils.py", line 102, in execute
    return super().execute(sql, params)
           ~~~~~~~~~~~~~~~^^^^^^^^^^^^^
  File "D:\projects\kindbite\backend\venv\Lib\site-packages\django\db\backends\utils.py", line 67, in execute
    return self._execute_with_wrappers(
           ~~~~~~~~~~~~~~~~~~~~~~~~~~~^
        sql, params, many=False, executor=self._execute
        ^^^^^^^^^^^^^^^^^^^^^^^^^^^^^^^^^^^^^^^^^^^^^^^
    )
    ^
  File "D:\projects\kindbite\backend\venv\Lib\site-packages\django\db\backends\utils.py", line 80, in _execute_with_wrappers
    return executor(sql, params, many, context)
  File "D:\projects\kindbite\backend\venv\Lib\site-packages\django\db\backends\utils.py", line 84, in _execute
    with self.db.wrap_database_errors:
         ^^^^^^^^^^^^^^^^^^^^^^^^^^^^
  File "D:\projects\kindbite\backend\venv\Lib\site-packages\django\db\utils.py", line 91, in __exit__
    raise dj_exc_value.with_traceback(traceback) from exc_value
  File "D:\projects\kindbite\backend\venv\Lib\site-packages\django\db\backends\utils.py", line 89, in _execute
    return self.cursor.execute(sql, params)
           ~~~~~~~~~~~~~~~~~~~^^^^^^^^^^^^^
  File "D:\projects\kindbite\backend\venv\Lib\site-packages\django\db\backends\sqlite3\base.py", line 328, in execute
    return super().execute(query, params)
           ~~~~~~~~~~~~~~~^^^^^^^^^^^^^^^
django.db.utils.OperationalError: no such table: users
"POST /api/v1/auth/register/ HTTP/1.1" 500 206210
Internal Server Error: /api/v1/auth/login/
Traceback (most recent call last):
  File "D:\projects\kindbite\backend\venv\Lib\site-packages\django\db\backends\utils.py", line 89, in _execute
    return self.cursor.execute(sql, params)
           ~~~~~~~~~~~~~~~~~~~^^^^^^^^^^^^^
  File "D:\projects\kindbite\backend\venv\Lib\site-packages\django\db\backends\sqlite3\base.py", line 328, in execute
    return super().execute(query, params)
           ~~~~~~~~~~~~~~~^^^^^^^^^^^^^^^
sqlite3.OperationalError: no such table: users

The above exception was the direct cause of the following exception:

Traceback (most recent call last):
  File "D:\projects\kindbite\backend\venv\Lib\site-packages\django\core\handlers\exception.py", line 55, in inner
    response = get_response(request)
  File "D:\projects\kindbite\backend\venv\Lib\site-packages\django\core\handlers\base.py", line 197, in _get_response
    response = wrapped_callback(request, *callback_args, **callback_kwargs)
  File "D:\projects\kindbite\backend\venv\Lib\site-packages\django\views\decorators\csrf.py", line 56, in wrapper_view
    return view_func(*args, **kwargs)
  File "D:\projects\kindbite\backend\venv\Lib\site-packages\django\views\generic\base.py", line 104, in view
    return self.dispatch(request, *args, **kwargs)
           ~~~~~~~~~~~~~^^^^^^^^^^^^^^^^^^^^^^^^^^
  File "D:\projects\kindbite\backend\venv\Lib\site-packages\rest_framework\views.py", line 509, in dispatch
    response = self.handle_exception(exc)
  File "D:\projects\kindbite\backend\venv\Lib\site-packages\rest_framework\views.py", line 469, in handle_exception
    self.raise_uncaught_exception(exc)
    ~~~~~~~~~~~~~~~~~~~~~~~~~~~~~^^^^^
  File "D:\projects\kindbite\backend\venv\Lib\site-packages\rest_framework\views.py", line 480, in raise_uncaught_exception
    raise exc
  File "D:\projects\kindbite\backend\venv\Lib\site-packages\rest_framework\views.py", line 506, in dispatch
    response = handler(request, *args, **kwargs)
  File "D:\projects\kindbite\backend\apps\authentication\views.py", line 33, in post
    response = super().post(request, *args, **kwargs)
  File "D:\projects\kindbite\backend\venv\Lib\site-packages\rest_framework_simplejwt\views.py", line 44, in post
    serializer.is_valid(raise_exception=True)
    ~~~~~~~~~~~~~~~~~~~^^^^^^^^^^^^^^^^^^^^^^
  File "D:\projects\kindbite\backend\venv\Lib\site-packages\rest_framework\serializers.py", line 227, in is_valid
    self._validated_data = self.run_validation(self.initial_data)
                           ~~~~~~~~~~~~~~~~~~~^^^^^^^^^^^^^^^^^^^
  File "D:\projects\kindbite\backend\venv\Lib\site-packages\rest_framework\serializers.py", line 429, in run_validation
    value = self.validate(value)
  File "D:\projects\kindbite\backend\apps\authentication\serializers.py", line 33, in validate
    user = authenticate(
        request=self.context.get('request'),
        username=email,
        password=password
    )
  File "D:\projects\kindbite\backend\venv\Lib\site-packages\django\views\decorators\debug.py", line 42, in sensitive_variables_wrapper
    return func(*func_args, **func_kwargs)
  File "D:\projects\kindbite\backend\venv\Lib\site-packages\django\contrib\auth\__init__.py", line 77, in authenticate
    user = backend.authenticate(request, **credentials)
  File "D:\projects\kindbite\backend\venv\Lib\site-packages\django\contrib\auth\backends.py", line 46, in authenticate
    user = UserModel._default_manager.get_by_natural_key(username)
  File "D:\projects\kindbite\backend\venv\Lib\site-packages\django\contrib\auth\base_user.py", line 54, in get_by_natural_key
    return self.get(**{self.model.USERNAME_FIELD: username})
           ~~~~~~~~^^^^^^^^^^^^^^^^^^^^^^^^^^^^^^^^^^^^^^^^^
  File "D:\projects\kindbite\backend\venv\Lib\site-packages\django\db\models\manager.py", line 87, in manager_method
    return getattr(self.get_queryset(), name)(*args, **kwargs)
           ~~~~~~~~~~~~~~~~~~~~~~~~~~~~~~~~~~^^^^^^^^^^^^^^^^^
  File "D:\projects\kindbite\backend\venv\Lib\site-packages\django\db\models\query.py", line 633, in get
    num = len(clone)
  File "D:\projects\kindbite\backend\venv\Lib\site-packages\django\db\models\query.py", line 380, in __len__
    self._fetch_all()
    ~~~~~~~~~~~~~~~^^
  File "D:\projects\kindbite\backend\venv\Lib\site-packages\django\db\models\query.py", line 1881, in _fetch_all
    self._result_cache = list(self._iterable_class(self))
                         ~~~~^^^^^^^^^^^^^^^^^^^^^^^^^^^^
  File "D:\projects\kindbite\backend\venv\Lib\site-packages\django\db\models\query.py", line 91, in __iter__
    results = compiler.execute_sql(
        chunked_fetch=self.chunked_fetch, chunk_size=self.chunk_size
    )
  File "D:\projects\kindbite\backend\venv\Lib\site-packages\django\db\models\sql\compiler.py", line 1562, in execute_sql
    cursor.execute(sql, params)
    ~~~~~~~~~~~~~~^^^^^^^^^^^^^
  File "D:\projects\kindbite\backend\venv\Lib\site-packages\django\db\backends\utils.py", line 102, in execute
    return super().execute(sql, params)
           ~~~~~~~~~~~~~~~^^^^^^^^^^^^^
  File "D:\projects\kindbite\backend\venv\Lib\site-packages\django\db\backends\utils.py", line 67, in execute
    return self._execute_with_wrappers(
           ~~~~~~~~~~~~~~~~~~~~~~~~~~~^
        sql, params, many=False, executor=self._execute
        ^^^^^^^^^^^^^^^^^^^^^^^^^^^^^^^^^^^^^^^^^^^^^^^
    )
    ^
  File "D:\projects\kindbite\backend\venv\Lib\site-packages\django\db\backends\utils.py", line 80, in _execute_with_wrappers
    return executor(sql, params, many, context)
  File "D:\projects\kindbite\backend\venv\Lib\site-packages\django\db\backends\utils.py", line 84, in _execute
    with self.db.wrap_database_errors:
         ^^^^^^^^^^^^^^^^^^^^^^^^^^^^
  File "D:\projects\kindbite\backend\venv\Lib\site-packages\django\db\utils.py", line 91, in __exit__
    raise dj_exc_value.with_traceback(traceback) from exc_value
  File "D:\projects\kindbite\backend\venv\Lib\site-packages\django\db\backends\utils.py", line 89, in _execute
    return self.cursor.execute(sql, params)
           ~~~~~~~~~~~~~~~~~~~^^^^^^^^^^^^^
  File "D:\projects\kindbite\backend\venv\Lib\site-packages\django\db\backends\sqlite3\base.py", line 328, in execute
    return super().execute(query, params)
           ~~~~~~~~~~~~~~~^^^^^^^^^^^^^^^
django.db.utils.OperationalError: no such table: users
"POST /api/v1/auth/login/ HTTP/1.1" 500 213835
D:\projects\kindbite\backend\apps\users\models.py changed, reloading.
Watching for file changes with StatReloader
Watching for file changes with StatReloader
"OPTIONS /api/v1/auth/register/ HTTP/1.1" 200 0
Bad Request: /api/v1/auth/register/
"POST /api/v1/auth/register/ HTTP/1.1" 400 129
Bad Request: /api/v1/auth/register/
"POST /api/v1/auth/register/ HTTP/1.1" 400 129
"OPTIONS /api/v1/auth/login/ HTTP/1.1" 200 0
Bad Request: /api/v1/auth/login/
"POST /api/v1/auth/login/ HTTP/1.1" 400 51
Bad Request: /api/v1/auth/register/
"POST /api/v1/auth/register/ HTTP/1.1" 400 129
Internal Server Error: /api/v1/auth/register/
Traceback (most recent call last):
  File "D:\projects\kindbite\backend\venv\Lib\site-packages\django\core\handlers\exception.py", line 55, in inner
    response = get_response(request)
  File "D:\projects\kindbite\backend\venv\Lib\site-packages\django\core\handlers\base.py", line 197, in _get_response
    response = wrapped_callback(request, *callback_args, **callback_kwargs)
  File "D:\projects\kindbite\backend\venv\Lib\site-packages\django\views\decorators\csrf.py", line 56, in wrapper_view
    return view_func(*args, **kwargs)
  File "D:\projects\kindbite\backend\venv\Lib\site-packages\django\views\generic\base.py", line 104, in view
    return self.dispatch(request, *args, **kwargs)
           ~~~~~~~~~~~~~^^^^^^^^^^^^^^^^^^^^^^^^^^
  File "D:\projects\kindbite\backend\venv\Lib\site-packages\rest_framework\views.py", line 509, in dispatch
    response = self.handle_exception(exc)
  File "D:\projects\kindbite\backend\venv\Lib\site-packages\rest_framework\views.py", line 469, in handle_exception
    self.raise_uncaught_exception(exc)
    ~~~~~~~~~~~~~~~~~~~~~~~~~~~~~^^^^^
  File "D:\projects\kindbite\backend\venv\Lib\site-packages\rest_framework\views.py", line 480, in raise_uncaught_exception
    raise exc
  File "D:\projects\kindbite\backend\venv\Lib\site-packages\rest_framework\views.py", line 506, in dispatch
    response = handler(request, *args, **kwargs)
  File "D:\projects\kindbite\backend\venv\Lib\site-packages\rest_framework\decorators.py", line 50, in handler
    return func(*args, **kwargs)
  File "D:\projects\kindbite\backend\apps\authentication\views.py", line 57, in register
    user = serializer.save()
  File "D:\projects\kindbite\backend\venv\Lib\site-packages\rest_framework\serializers.py", line 212, in save
    self.instance = self.create(validated_data)
                    ~~~~~~~~~~~^^^^^^^^^^^^^^^^
  File "D:\projects\kindbite\backend\apps\users\serializers.py", line 69, in create
    user = User.objects.create_user(**validated_data)
TypeError: UserManager.create_user() missing 1 required positional argument: 'username'
"POST /api/v1/auth/register/ HTTP/1.1" 500 24937
D:\projects\kindbite\backend\apps\users\models.py changed, reloading.
Watching for file changes with StatReloader
D:\projects\kindbite\backend\apps\users\models.py changed, reloading.
Watching for file changes with StatReloader
Watching for file changes with StatReloader
"POST /api/v1/auth/register/ HTTP/1.1" 201 1602
"POST /api/v1/auth/login/ HTTP/1.1" 200 1765
D:\projects\kindbite\backend\kindbite\settings.py changed, reloading.
Watching for file changes with StatReloader
D:\projects\kindbite\backend\kindbite\settings.py changed, reloading.
Watching for file changes with StatReloader
D:\projects\kindbite\backend\apps\ai_chat\apps.py changed, reloading.
Watching for file changes with StatReloader
D:\projects\kindbite\backend\apps\ai_chat\__init__.py changed, reloading.
Watching for file changes with StatReloader
D:\projects\kindbite\backend\apps\ai_chat\__init__.py changed, reloading.
Watching for file changes with StatReloader
D:\projects\kindbite\backend\kindbite\settings.py changed, reloading.
Watching for file changes with StatReloader
D:\projects\kindbite\backend\apps\ai_chat\services.py changed, reloading.
Watching for file changes with StatReloader
D:\projects\kindbite\backend\apps\ai_chat\services.py changed, reloading.
Watching for file changes with StatReloader
D:\projects\kindbite\backend\apps\ai_chat\services.py changed, reloading.
Watching for file changes with StatReloader
D:\projects\kindbite\backend\apps\ai_chat\services.py changed, reloading.
Watching for file changes with StatReloader
D:\projects\kindbite\backend\kindbite\settings.py changed, reloading.
Watching for file changes with StatReloader
Watching for file changes with StatReloader
"OPTIONS /api/v1/chat/send/ HTTP/1.1" 200 0
Unauthorized: /api/v1/chat/send/
"POST /api/v1/chat/send/ HTTP/1.1" 401 183
"OPTIONS /api/v1/auth/token/refresh/ HTTP/1.1" 200 0
"POST /api/v1/auth/token/refresh/ HTTP/1.1" 200 667
"POST /api/v1/chat/send/ HTTP/1.1" 201 751
D:\projects\kindbite\backend\apps\ai_chat\services.py changed, reloading.
Watching for file changes with StatReloader
D:\projects\kindbite\backend\apps\ai_chat\services.py changed, reloading.
Watching for file changes with StatReloader
"OPTIONS /api/v1/auth/me/ HTTP/1.1" 200 0
"GET /api/v1/auth/me/ HTTP/1.1" 200 1049
D:\projects\kindbite\backend\apps\ai_chat\services.py changed, reloading.
Watching for file changes with StatReloader
"POST /api/v1/chat/send/ HTTP/1.1" 201 600
"POST /api/v1/chat/send/ HTTP/1.1" 201 643
"POST /api/v1/chat/send/ HTTP/1.1" 201 711
"POST /api/v1/chat/send/ HTTP/1.1" 201 1255
D:\projects\kindbite\backend\kindbite\settings.py changed, reloading.
Watching for file changes with StatReloader
D:\projects\kindbite\backend\kindbite\settings.py changed, reloading.
Watching for file changes with StatReloader
"OPTIONS /api/v1/foods/stats/ HTTP/1.1" 200 0
Unauthorized: /api/v1/foods/stats/
"GET /api/v1/foods/stats/ HTTP/1.1" 401 183
"OPTIONS /api/v1/auth/token/refresh/ HTTP/1.1" 200 0
"POST /api/v1/auth/token/refresh/ HTTP/1.1" 200 667
Internal Server Error: /api/v1/foods/stats/
Traceback (most recent call last):
  File "D:\projects\kindbite\backend\venv\Lib\site-packages\django\db\backends\utils.py", line 89, in _execute
    return self.cursor.execute(sql, params)
           ~~~~~~~~~~~~~~~~~~~^^^^^^^^^^^^^
  File "D:\projects\kindbite\backend\venv\Lib\site-packages\django\db\backends\sqlite3\base.py", line 328, in execute
    return super().execute(query, params)
           ~~~~~~~~~~~~~~~^^^^^^^^^^^^^^^
sqlite3.OperationalError: no such table: food_listings

The above exception was the direct cause of the following exception:

Traceback (most recent call last):
  File "D:\projects\kindbite\backend\venv\Lib\site-packages\django\core\handlers\exception.py", line 55, in inner
    response = get_response(request)
  File "D:\projects\kindbite\backend\venv\Lib\site-packages\django\core\handlers\base.py", line 197, in _get_response
    response = wrapped_callback(request, *callback_args, **callback_kwargs)
  File "D:\projects\kindbite\backend\venv\Lib\site-packages\django\views\decorators\csrf.py", line 56, in wrapper_view
    return view_func(*args, **kwargs)
  File "D:\projects\kindbite\backend\venv\Lib\site-packages\django\views\generic\base.py", line 104, in view
    return self.dispatch(request, *args, **kwargs)
           ~~~~~~~~~~~~~^^^^^^^^^^^^^^^^^^^^^^^^^^
  File "D:\projects\kindbite\backend\venv\Lib\site-packages\rest_framework\views.py", line 509, in dispatch
    response = self.handle_exception(exc)
  File "D:\projects\kindbite\backend\venv\Lib\site-packages\rest_framework\views.py", line 469, in handle_exception
    self.raise_uncaught_exception(exc)
    ~~~~~~~~~~~~~~~~~~~~~~~~~~~~~^^^^^
  File "D:\projects\kindbite\backend\venv\Lib\site-packages\rest_framework\views.py", line 480, in raise_uncaught_exception
    raise exc
  File "D:\projects\kindbite\backend\venv\Lib\site-packages\rest_framework\views.py", line 506, in dispatch
    response = handler(request, *args, **kwargs)
  File "D:\projects\kindbite\backend\venv\Lib\site-packages\rest_framework\decorators.py", line 50, in handler
    return func(*args, **kwargs)
  File "D:\projects\kindbite\backend\apps\foods\views.py", line 199, in food_stats
    total_listings = queryset.count()
  File "D:\projects\kindbite\backend\venv\Lib\site-packages\django\db\models\query.py", line 608, in count
    return self.query.get_count(using=self.db)
           ~~~~~~~~~~~~~~~~~~~~^^^^^^^^^^^^^^^
  File "D:\projects\kindbite\backend\venv\Lib\site-packages\django\db\models\sql\query.py", line 568, in get_count
    return obj.get_aggregation(using, {"__count": Count("*")})["__count"]
           ~~~~~~~~~~~~~~~~~~~^^^^^^^^^^^^^^^^^^^^^^^^^^^^^^^^
  File "D:\projects\kindbite\backend\venv\Lib\site-packages\django\db\models\sql\query.py", line 554, in get_aggregation
    result = compiler.execute_sql(SINGLE)
  File "D:\projects\kindbite\backend\venv\Lib\site-packages\django\db\models\sql\compiler.py", line 1562, in execute_sql
    cursor.execute(sql, params)
    ~~~~~~~~~~~~~~^^^^^^^^^^^^^
  File "D:\projects\kindbite\backend\venv\Lib\site-packages\django\db\backends\utils.py", line 102, in execute
    return super().execute(sql, params)
           ~~~~~~~~~~~~~~~^^^^^^^^^^^^^
  File "D:\projects\kindbite\backend\venv\Lib\site-packages\django\db\backends\utils.py", line 67, in execute
    return self._execute_with_wrappers(
           ~~~~~~~~~~~~~~~~~~~~~~~~~~~^
        sql, params, many=False, executor=self._execute
        ^^^^^^^^^^^^^^^^^^^^^^^^^^^^^^^^^^^^^^^^^^^^^^^
    )
    ^
  File "D:\projects\kindbite\backend\venv\Lib\site-packages\django\db\backends\utils.py", line 80, in _execute_with_wrappers
    return executor(sql, params, many, context)
  File "D:\projects\kindbite\backend\venv\Lib\site-packages\django\db\backends\utils.py", line 84, in _execute
    with self.db.wrap_database_errors:
         ^^^^^^^^^^^^^^^^^^^^^^^^^^^^
  File "D:\projects\kindbite\backend\venv\Lib\site-packages\django\db\utils.py", line 91, in __exit__
    raise dj_exc_value.with_traceback(traceback) from exc_value
  File "D:\projects\kindbite\backend\venv\Lib\site-packages\django\db\backends\utils.py", line 89, in _execute
    return self.cursor.execute(sql, params)
           ~~~~~~~~~~~~~~~~~~~^^^^^^^^^^^^^
  File "D:\projects\kindbite\backend\venv\Lib\site-packages\django\db\backends\sqlite3\base.py", line 328, in execute
    return super().execute(query, params)
           ~~~~~~~~~~~~~~~^^^^^^^^^^^^^^^
django.db.utils.OperationalError: no such table: food_listings
"GET /api/v1/foods/stats/ HTTP/1.1" 500 27699
Watching for file changes with StatReloader
"OPTIONS /api/v1/auth/login/ HTTP/1.1" 200 0
"POST /api/v1/auth/login/ HTTP/1.1" 200 1765
"OPTIONS /api/v1/chat/send/ HTTP/1.1" 200 0
"POST /api/v1/chat/send/ HTTP/1.1" 201 743
